<?xml version="1.0"?>
<robot name="rick">

<!-- White Material -->
    <material name="white">
        <color rgba="1 1 1 1"/>
    </material>
    <!-- Black Material -->
    <material name="black">
        <color rgba="0 0 0 1"/>
    </material>

    <material name="blue">
        <color rgba="0 0 0.8 1" />
      </material>
<!-- links -->
<!-- base_link -->
  <link name="base_link">
    <visual>
      <geometry>
        <cylinder length="0.155" radius="0.178" />
      </geometry>
      <material name="blue">
        <color rgba="0 0 0.8 1" />
      </material>
    </visual>
    <collision>
      <origin rpy="0 0 0" xyz="0 0 0"/>
      <geometry>
        <cylinder length="0.155" radius="0.178" />
      </geometry>
    </collision>
    <inertial>
      <mass value="12" />
      <origin rpy="0 0 0" xyz="0 0 0"/>
      <inertia ixx="0.11908" ixy="0.0" ixz="0.0" iyy="0.11908" iyz="0.0" izz="0.1901" />
    </inertial>
  </link>

<!-- standoff-rod_a -->
  <link name="rod_a">
    <visual>
      <origin rpy="0 0 0" xyz="0 0 0"/>
      <geometry>
        <cylinder radius="0.01" length="0.22"/>
      </geometry>
      <material name="white"/>
    </visual>
    <collision>
      <origin rpy="0 0 0" xyz="0 0 0"/>
      <geometry>
        <cylinder length="0.01" radius="0.22" />
      </geometry>
    </collision>
    <inertial>
            <mass value="0.25"/>
            <origin rpy="0 0 0" xyz="0 0 0"/>
            <inertia ixx="0.001015" ixy="0" ixz="0" iyy="0.001015" iyz="0" izz="0.000013"/>
        </inertial>
  </link>


<!-- standoff-rod_b -->
  <link name="rod_b">
    <visual>
      <origin rpy="0 0 0" xyz="0 0 0"/>
      <geometry>
        <cylinder radius="0.01" length="0.22"/>
      </geometry>
      <material name="white"/>
    </visual>
    <collision>
      <origin rpy="0 0 0" xyz="0 0 0"/>
      <geometry>
        <cylinder length="0.01" radius="0.22" />
      </geometry>
    </collision>
    <inertial>
            <mass value="0.25"/>
            <origin rpy="0 0 0" xyz="0 0 0"/>
            <inertia ixx="0.001015" ixy="0" ixz="0" iyy="0.001015" iyz="0" izz="0.000013"/>
        </inertial>
  </link>

<!-- standoff-rod_c -->
  <link name="rod_c">
    <visual>
      <origin rpy="0 0 0" xyz="0 0 0"/>
      <geometry>
        <cylinder radius="0.01" length="0.22"/>
      </geometry>
      <material name="white"/>
    </visual>
    <collision>
      <origin rpy="0 0 0" xyz="0 0 0"/>
      <geometry>
        <cylinder length="0.01" radius="0.22" />
      </geometry>
    </collision>
    <inertial>
            <mass value="0.25"/>
            <origin rpy="0 0 0" xyz="0 0 0"/>
            <inertia ixx="0.001015" ixy="0" ixz="0" iyy="0.001015" iyz="0" izz="0.000013"/>
        </inertial>
  </link> 

<!-- standoff-rod_d -->
  <link name="rod_d">
    <visual>
      <origin rpy="0 0 0" xyz="0 0 0"/>
      <geometry>
        <cylinder radius="0.01" length="0.22"/>
      </geometry>
      <material name="white"/>
    </visual>
    <collision>
      <origin rpy="0 0 0" xyz="0 0 0"/>
      <geometry>
        <cylinder length="0.01" radius="0.22" />
      </geometry>
    </collision>
    <inertial>
            <mass value="0.25"/>
            <origin rpy="0 0 0" xyz="0 0 0"/>
            <inertia ixx="0.001015" ixy="0" ixz="0" iyy="0.001015" iyz="0" izz="0.000013"/>
        </inertial>
  </link> 

<!-- right-wheel -->
  <link name="right_wheel">
    <visual>
      <origin rpy="1.570796  0 0" xyz="0 0 0"/>
      <geometry>
        <cylinder radius="0.0352" length="0.0206"/>
      </geometry>
      <material name="black"/>
    </visual>
    <collision>
      <origin rpy="1.570796  0 0" xyz="0 0 0"/>
      <geometry>
        <cylinder length="0.0352" radius="0.0206" />
      </geometry>
    </collision>
    <inertial>
            <mass value="0.25"/>
            <origin rpy="1.570796 0 0" xyz="0 0 0"/>
            <inertia ixx="0.000058" ixy="0" ixz="0" iyy="0.000058" iyz="0" izz="0.000050"/>
        </inertial>
  </link>

<!-- left-wheel -->
  <link name="left_wheel">
    <visual>
      <origin rpy="1.570796 0 0" xyz="0 0 0"/>
      <geometry>
        <cylinder radius="0.0352" length="0.0206"/>
      </geometry>
      <material name="black"/>
    </visual>
    <collision>
      <origin rpy="1.570796  0 0" xyz="0 0 0"/>
      <geometry>
        <cylinder length="0.0352" radius="0.0206" />
      </geometry>
    </collision>
    <inertial>
            <mass value="0.25"/>
            <origin rpy="1.570796 0 0" xyz="0 0 0"/>
            <inertia ixx="0.000058" ixy="0" ixz="0" iyy="0.000058" iyz="0" izz="0.000050"/>
        </inertial>
  </link> 

<!-- front_caster -->
  <link name="front_caster">
    <visual>
      <origin rpy="0 0 0" xyz="0 0 0"/>
      <geometry>
        <sphere radius="0.020"/>
      </geometry>
      <material name="black"/>
    </visual>
    <collision>
      <geometry>
        <sphere radius="0.020"/>
      </geometry>
    </collision>
    <inertial>
            <mass value="0.25"/>
            <origin rpy="0 0 0" xyz="0 0 0"/>
            <inertia ixx="0.000040" ixy="0" ixz="0" iyy="0.000040" iyz="0" izz="0.000040"/>
        </inertial>
  </link>

<!-- back_caster -->
  <link name="back_caster">
    <visual>
      <origin rpy="0 0 0" xyz="0 0 0"/>
      <geometry>
        <sphere radius="0.020"/>
      </geometry>
      <material name="black"/>
    </visual>
    <collision>
      <geometry>
        <sphere radius="0.020"/>
      </geometry>
    </collision>
    <inertial>
            <mass value="0.25"/>
            <origin rpy="0 0 0" xyz="0 0 0"/>
            <inertia ixx="0.000040" ixy="0" ixz="0" iyy="0.000040" iyz="0" izz="0.000040"/>
        </inertial>
  </link>

<!-- cup_holder -->
  <link name="cup_holder">
    <visual>
      <origin rpy="0 0 0" xyz="0 0 0"/>
      <geometry>
        <cylinder radius="0.16" length="0.09"/>
      </geometry>
      <material name="blue">
        <color rgba="0.0 0.0 1.0 1"/>
      </material>
    </visual>
    <collision>
      <geometry>
        <cylinder radius="0.16" length="0.09"/>
      </geometry>
    </collision>
    <inertial>
            <mass value="6"/>
            <origin rpy="0 0 0" xyz="0 0 0"/>
            <inertia ixx="0.042450" ixy="0" ixz="0" iyy="0.042450" iyz="0" izz="0.076800"/>
        </inertial>
  </link>


<!-- joints -->
  <joint name="base_link_to_rod_a" type="fixed">
    <parent link="base_link"/>
    <child link="rod_a"/>
    <origin xyz="0.040 0.125 0.1875" rpy="0 0 0"/>
  </joint>

  <joint name="base_link_to_rod_b" type="fixed">
    <parent link="base_link"/>
    <child link="rod_b"/>
    <origin xyz="-0.040 0.125 0.1875" rpy="0 0 0"/>
  </joint>

  <joint name="base_link_to_rod_c" type="fixed">
    <parent link="base_link"/>
    <child link="rod_c"/>
    <origin xyz="0.040 -0.125 0.1875" rpy="0 0 0"/>
  </joint>

  <joint name="base_link_to_rod_d" type="fixed">
    <parent link="base_link"/>
    <child link="rod_d"/>
    <origin xyz="-0.040 -0.125 0.1875" rpy="0 0 0"/>
  </joint>

  <joint name="base_link_to_right_wheel" type="continuous">
    <parent link="base_link"/>
    <child link="right_wheel"/>
    <origin xyz="0 0.145 -0.0775" rpy="0 0 0"/>
    <axis xyz="0 0 1"/>
    <limit effort="10000" velocity="1000" />
    <joint_properties damping="1.0" friction="1.0"/>
  </joint>

  <joint name="base_link_to_left_wheel" type="continuous">
    <parent link="base_link"/>
    <child link="left_wheel"/>
    <origin xyz="0 -0.145 -0.0775" rpy="0 0 0"/>
    <axis xyz="0 0 1"/>
    <limit effort="10000" velocity="1000" />
    <joint_properties damping="1.0" friction="1.0"/>
  </joint>

  <joint name="base_link_to_front_caster" type="fixed">
    <parent link="base_link"/>
    <child link="front_caster"/>
    <origin xyz="0.145 0 -0.0775" rpy="0 0 0"/>
    <axis xyz="0 1 0"/>
    <joint_properties damping="1.0" friction="1.0"/>
  </joint>

  <joint name="base_link_to_back_caster" type="fixed">
    <parent link="base_link"/>
    <child link="back_caster"/>
    <origin xyz="-0.145 0 -0.0775" rpy="0 0 0"/>
    <axis xyz="0 1 0"/>
    <joint_properties damping="1.0" friction="1.0"/>
  </joint> 

  <joint name="base_link_to_cup_holder" type="fixed">
  <parent link="base_link"/>
  <child link="cup_holder"/>
  <origin xyz="0 0 0.330" rpy="0 0 0"/>
</joint>


    <!-- Joint State Plugin -->
    <gazebo>
        <plugin name="barista_bot_joint_state" filename="libgazebo_ros_joint_state_publisher.so">
            <ros>
                <remapping>~/out:=joint_states</remapping>
            </ros>
            <update_rate>30</update_rate>
            <joint_name>base_link_to_left_wheel</joint_name>
            <joint_name>base_link_to_right_wheel</joint_name>
        </plugin>
    </gazebo>
    <!-- Differential Drive Plugin -->
    <gazebo>
        <plugin filename="libgazebo_ros_diff_drive.so" name="differential_drive_controller">
            <!-- wheels -->
            <left_joint>base_link_to_left_wheel</left_joint>
            <right_joint>base_link_to_right_wheel</right_joint>
            <!-- kinematics -->
            <wheel_separation>0.29</wheel_separation>
            <wheel_diameter>0.04</wheel_diameter>
            <!-- limits -->
            <max_wheel_torque>1.0</max_wheel_torque>
            <max_wheel_acceleration>2.0</max_wheel_acceleration>
            <!-- output -->
            <publish_odom>true</publish_odom>
            <publish_odom_tf>true</publish_odom_tf>
            <odometry_frame>odom</odometry_frame>
            <robot_base_frame>base_link</robot_base_frame>
        </plugin>
    </gazebo>

<!-- gazebo_references -->
<gazebo reference="base_link">
        <material>Gazebo/Blue</material>
    </gazebo>
<gazebo reference="cup_holder">
        <material>Gazebo/Blue</material>
    </gazebo>    
<gazebo reference="rod_a">
        <material>Gazebo/White</material>
    </gazebo>
<gazebo reference="rod_b">
        <material>Gazebo/White</material>
    </gazebo> 
<gazebo reference="rod_c">
        <material>Gazebo/White</material>
    </gazebo>   
<gazebo reference="rod_d">
        <material>Gazebo/White</material>
    </gazebo> 
<gazebo reference="right_wheel">
        <kp>1e6</kp>
        <kd>10</kd>
        <mu1>10.0</mu1>
        <mu2>10.0</mu2>
        <material>Gazebo/Black</material>
    </gazebo>
<gazebo reference="left_wheel">
        <kp>1e6</kp>
        <kd>10</kd>
        <mu1>10.0</mu1>
        <mu2>10.0</mu2>
        <material>Gazebo/Black</material>
    </gazebo>  
 <gazebo reference="front_caster">
        <kp>1e6</kp>
        <kd>10</kd>
        <mu1>0.0</mu1>
        <mu2>0.0</mu2>
        <material>Gazebo/Black</material>
    </gazebo>  
<gazebo reference="back_caster">
        <kp>1e6</kp>
        <kd>10</kd>
        <mu1>0.0</mu1>
        <mu2>0.0</mu2>
        <material>Gazebo/Black</material>
    </gazebo>                 
<gazebo reference="base_link_to_front_caster">
        <preserveFixedJoint>true</preserveFixedJoint>
    </gazebo>
<gazebo reference="base_link_to_back_caster">
        <preserveFixedJoint>true</preserveFixedJoint>
    </gazebo>    

</robot>